Workbook

Sheet Resumo 
A1: Nº | B1: FORNECEDOR | C1: VALOR ORÇAMENTO | D1: FORMA DE PAGAMENTO | E1: LOCAL DE ENTREGA | F1: DADOS DE PAGAMENTO | G1: STATUS DA COMPRA | H1: NOTA FISCAL
A2: 1 | B2: CELMAT | C2: =SUMIF('Tabela padrão - Suprimentos méd'!#REF!,'Resumo '!B2,'Tabela padrão - Suprimentos méd'!#REF!) -> #REF! | D2: À VISTA | E2: STRALOG | F2: Banco Bradesco Ag. 0287 C/C 4553-5 VAD MEDICAL | G2: REALIZAR PAGAMENTO
A3: 2 | B3: CIRURGICA ESTILO | C3: =SUMIF('Tabela padrão - Suprimentos méd'!#REF!,'Resumo '!B3,'Tabela padrão - Suprimentos méd'!#REF!) -> #REF! | D3: CARTÃO DE CRÉDITO | E3: ESCRITÓRIO | F3: CARTÃO DE CRÉDITO | G3: NF | H3: 3596
A4: 3 | B4: CIRURGICA ATLANTICA | C4: =SUMIF('Tabela padrão - Suprimentos méd'!#REF!,'Resumo '!B4,'Tabela padrão - Suprimentos méd'!#REF!) -> #REF! | D4: À VISTA | E4: STRALOG | F4: PIX: 55.666.777/0001-81 CIRURGICA ATLANTICA C.MAT.CIR.HO.SO. LTDA | G4: NF | H4: 1437267
A5: 4 | B5: CIRURGICA PASSOS | C5: =SUMIF('Tabela padrão - Suprimentos méd'!#REF!,'Resumo '!B5,'Tabela padrão - Suprimentos méd'!#REF!) -> #REF! | D5: À VISTA | E5: STRALOG | G5: REALIZAR PAGAMENTO
A6: 5 | B6: CLARAMED | C6: =SUMIF('Tabela padrão - Suprimentos méd'!#REF!,'Resumo '!B6,'Tabela padrão - Suprimentos méd'!#REF!) -> #REF! | D6: À VISTA | E6: STRALOG | F6: Banco Santander Agencia 4628 C/c 13003351-0 Cnpj :99.000.111/0001-65 | G6: REALIZAR PAGAMENTO
A7: 6 | B7: FIBRA CIRÚRGICA | C7: =SUMIF('Tabela padrão - Suprimentos méd'!#REF!,'Resumo '!B7,'Tabela padrão - Suprimentos méd'!#REF!) -> #REF! | D7: CARTÃO DE CRÉDITO | E7: STRALOG | F7: CARTÃO DE CRÉDITO | G7: COMPRADO SITE | H7: 469301
A8: 7 | B8: HOSPITALAR | C8: =SUMIF('Tabela padrão - Suprimentos méd'!#REF!,'Resumo '!B8,'Tabela padrão - Suprimentos méd'!#REF!) -> #REF! | G8: Não é possivel mais realizar compras
A9: 8 | B9: KALUNGA | C9: =SUMIF('Tabela padrão - Suprimentos méd'!#REF!,'Resumo '!B9,'Tabela padrão - Suprimentos méd'!#REF!) -> #REF! | D9: CARTÃO DE CRÉDITO | E9: ESCRITÓRIO | F9: CARTÃO DE CRÉDITO | G9: COMPRADO SITE
A10: 9 | B10: MAGAZINE MÉDICA | C10: =SUMIF('Tabela padrão - Suprimentos méd'!#REF!,'Resumo '!B10,'Tabela padrão - Suprimentos méd'!#REF!) -> #REF! | D10: CARTÃO DE CRÉDITO | E10: STRALOG | F10: CARTÃO DE CRÉDITO | G10: COMPRADO SITE
A11: 10 | B11: MNP | C11: =SUMIF('Tabela padrão - Suprimentos méd'!#REF!,'Resumo '!B11,'Tabela padrão - Suprimentos méd'!#REF!) -> #REF! | D11: À VISTA | E11: STRALOG | F11: Banco: Bradesco 7808-5 Conta corrente. 0008367-4 CNPJ 88.999.000/0001-98 | G11: REALIZAR PAGAMENTO
A12: 11 | B12: NEWMED | C12: =SUMIF('Tabela padrão - Suprimentos méd'!#REF!,'Resumo '!B12,'Tabela padrão - Suprimentos méd'!#REF!) -> #REF! | D12: À VISTA | E12: STRALOG | F12: NEWMED PRODUTOS PARA SAUDE LTDA - PIX CNPJ: 1aeb7ac5-8299-42fb-aad3-89bfb82ef807 | G12: REALIZAR PAGAMENTO
A13: 12 | B13: PRODUTOS HOSPITALARES ONLINE | C13: =SUMIF('Tabela padrão - Suprimentos méd'!#REF!,'Resumo '!B13,'Tabela padrão - Suprimentos méd'!#REF!) -> #REF! | D13: CARTÃO DE CRÉDITO | E13: STRALOG | F13: CARTÃO DE CRÉDITO | G13: COMPRADO SITE
A14: 13 | B14: SUPER EPI | C14: =SUMIF('Tabela padrão - Suprimentos méd'!#REF!,'Resumo '!B14,'Tabela padrão - Suprimentos méd'!#REF!) -> #REF! | D14: CARTÃO DE CRÉDITO | E14: ESCRITÓRIO | F14: CARTÃO DE CRÉDITO | G14: NF | H14: 125870
A15: 14 | B15: MEDSUL | C15: 15051.35 | D15: À VISTA | E15: STRALOG | F15: CNPJ: 11222333000181 | G15: REALIZAR PAGAMENTO
A16: 15 | B16: UTILIDADES MÉDICAS | C16: =SUMIF('Tabela padrão - Suprimentos méd'!#REF!,'Resumo '!B16,'Tabela padrão - Suprimentos méd'!#REF!) -> #REF! | D16: CARTÃO DE CRÉDITO | E16: ESCRITÓRIO | F16: CARTÃO DE CRÉDITO | G16: NF | H16: 4180749
A17: 16 | B17: VERBENNA | C17: =SUMIF('Tabela padrão - Suprimentos méd'!#REF!,'Resumo '!B17,'Tabela padrão - Suprimentos méd'!#REF!) -> #REF! | D17: À VISTA | E17: ESCRITÓRIO
A18: 17 | B18: Newvita | C18: =SUMIF('Tabela padrão - Suprimentos méd'!#REF!,'Resumo '!B18,'Tabela padrão - Suprimentos méd'!#REF!) -> #REF! | D18: CARTÃO DE CRÉDITO | E18: STRALOG | F18: CARTÃO DE CRÉDITO | G18: COMPRADO SITE
B19: VALOR TOTAL | C19: =SUM(C2:C18) -> #REF!

Sheet Tabela padrão - Suprimentos méd
A1: DESCRIÇÃO | B1: QUANTIDADE | C1: OBSERVAÇÃO | D1: NCM | E1: UNIDADE DE MEDIDA | F1: Classificação | G1: SETOR
A2: ABAIXADOR DE LINGUA INFANTL | B2: 2 | C2: COMPRAR NO LOCAL | D2: 90189099 | E2: PACOTE | F2: Itens cirúrgicos | G2: TRIAGEM - PEDIATRIA
A3: ABAIXADOR DE LINGUA MADEIRA PCT C/100 | B3: 10 | C3: COMPRAR NO LOCAL | D3: 90189099 | E3: PACOTE | F3: Itens cirúrgicos | G3: TRIAGEM/ PRÉ E PÓS
A4: ALCOOL 70% | B4: 10 | C4: COMPRAR NO LOCAL
A5: ALCOOL EM GEL - 500ML | B5: 20 | C5: COMPRAR NO LOCAL
A6: ÁCIDO TRANEXÂMICO 5ML | B6: 60 | C6: Considerar 1 ampola por paciente | D6: 90189010 | E6: UNIDADE | F6: Medicamento | G6: ANESTESIA - MEDICAMENTOS
A7: ADAPTADOR VACUNTAINER PARA COLETA DE SANGUE A VACUO | B7: 4 | C7: Pedir para o hospital | D7: 90183119 | E7: UNIDADE | F7: Itens cirúrgicos | G7: Triagem - Coleta de sangue
A8: ADENOSINA 3MG/ML - AMPOLA 2ML -SOLUCAO INJETAVEL | B8: 10 | D8: 29349129 | E8: UNIDADE | F8: Medicamento | G8: ANESTESIA - MEDICAMENTOS
A9: ADESIVO DERMABOND 5 ML | B9: 5 | C9: DOAÇÃO J&J | D9: 30061090 | E9: CAIXA | F9: Itens cirúrgicos | G9: FIO DE SUTURA
A10: ADRENALINA 1MG/ML AMPOLA 1ML SOLUCAO INJETAVEL | B10: 100 | D10: 30049021 | E10: UNIDADE | F10: Medicamento | G10: ANESTESIA - MEDICAMENTOS
A11: AGUA DESTILADA PARA INJEÇÃO - AMPOLA 10ML - SOLUÇÃ+A1:P376O INJETÁVEL | B11: 100 | D11: 30049099 | E11: UNIDADE | F11: Medicamento | G11: ANESTESIA - MEDICAMENTOS
A12: AGULHA HIPODERMICA DESCARTAVEL 21GX1.1/2 (40X08) | B12: 300 | D12: 90183219 | E12: UNIDADE | F12: Itens cirúrgicos | G12: OR
A13: AGULHA HIPODERMICA DESCARTAVEL 18GX1.1/2 (40X12) | B13: 300 | D13: 90183219 | E13: UNIDADE | F13: Itens cirúrgicos | G13: OR
A14: AGULHA HIPODERMICA DESCARTAVEL 19G 1.1 (30X10) | B14: 300 | D14: 90183219 | E14: UNIDADE | F14: Itens cirúrgicos | G14: OR
A15: AGULHA HIPODERMICA DESCARTAVEL 23GX1(25X6) | B15: 300 | D15: 90183219 | E15: UNIDADE | F15: Itens cirúrgicos | G15: OR
A16: AGULHA HIPODERMICA DESCARTAVEL 25G X 5/8" (25X08) | B16: 200 | D16: 90183219 | E16: UNIDADE | F16: Itens cirúrgicos | G16: OR
A17: ALMOFADA PARA ASSEPSSIA COM ALCOOL 70% (ALCOHOL SWAB SACHE) - CAIXA C/ 200 SACHES | B17: 5 | C17: COMPRAR NO LOCAL | D17: 30059090 | E17: UNIDADE | F17: Itens cirúrgicos | G17: OR
A18: AMINOFILINA 250 MG (25MG/ML) - AMPOLA 10 ML - SOLUÇÃO INJETÁVEL | B18: 3 | D18: 30049099 | E18: UNIDADE | F18: Medicamento | G18: ANESTESIA - MEDICAMENTOS
A19: AMOXICILINA 250MG/5ML-SUPENSAO ORAL-FRASCO | B19: 50 | C19: Comprar no local - Após reunião de Team Leaders | D19: 30049099 | E19: UNIDADE | F19: Medicamento | G19: PRÉ E PÓS
A20: ASPIRADOR CIRURGICO C/EXTENSAO 3.0 METROS-CANULA YANKAUER | B20: 80 | C20: 1 por paciente | D20: 90183929 | E20: UNIDADE | F20: Itens cirúrgicos | G20: KIT BASICO POR CIRURGIA
A21: AVENTAL CIRURGICO DES ESTERIL TAM EXTRA GRANDE | B21: =4*62 -> 248 | C21: 3 por paciente (CP full+CP OBS+Instrumentador) | D21: 62101000 | E21: UNIDADE | F21: Itens cirúrgicos | G21: KIT BASICO POR CIRURGIA
A22: AZITROMICINA 500 MG - COMPRIMIDOS | B22: 10 | C22: COMPRAR NO LOCAL | D22: 30042029 | E22: UNIDADE | F22: Medicamento | G22: PRÉ E PÓS/ KIT DO TIME
A23: AZITROMICINA DI-HIDRATADA 500MG - PÓ LIOFILIZADO P/ INFUSÃO - SOLUÇÃO INJETÁVEL | B23: 5 | C23: DOAÇÃO CRISTÁLIA | D23: 30042029 | E23: UNIDADE | F23: Itens cirúrgicos | G23: ANESTESIA - MEDICAMENTOS
A24: AZUL DE METILENO 1% - AMPOLA 2ML - SOLUCAO ESTERIL | B24: 20 | D24: 29343090 | E24: UNIDADE | F24: Medicamento | G24: OR
A25: BROMETO DE IPRATRÓPIO 0,25MG/ML - FRASCO 20ML | B25: 3 | C25: COMPRAR NO LOCAL | D25: 30049099 | E25: UNIDADE | F25: Medicamento | G25: PRÉ E PÓS/RECUPERAÇÃO
A26: BROMETO DE ROCURÔNIO 10MG/ML - FRASCO 5ML - SOLUÇÃO INJETÁVEL | B26: 15 | C26: DOAÇÃO CRISTÁLIA | D26: 30049099 | E26: UNIDADE | F26: Itens cirúrgicos | G26: ANESTESIA - MEDICAMENTOS
A27: BROMIDRATO DE FENOTEROL 100MCG 10ML AEROSOL | B27: 2 | C27: COMPRAR NO LOCAL | D27: 30049039 | E27: UNIDADE | F27: Medicamento | G27: PRÉ E PÓS/RECUPERAÇÃO
A28: BROMIDRATO DE FENOTEROL 5MG/ML - SOLUÇÃO PARA NEBULIZAÇÃO | B28: 2 | C28: COMPRAR NO LOCAL | D28: 30049039 | E28: UNIDADE | F28: Medicamento | G28: PRÉ E PÓS/RECUPERAÇÃO
A29: BUPIVACAÍNA 25% - COM ADRENALINA - AMPOLA 50ML 1:200,000 - SOLUÇÃO INJETÁVEL | B29: 20 | C29: DOAÇÃO CRISTÁLIA | G29: ANESTESIA - MEDICAMENTOS
A30: BUPIVACAÍNA 0.5% - SEM ADRENALINA - AMPOLA 20ML - SOLUÇÃO INJETÁVEL | B30: 50 | C30: DOAÇÃO CRISTÁLIA | D30: 30049061 | E30: UNIDADE | F30: Itens cirúrgicos | G30: ANESTESIA - MEDICAMENTOS
A31: CAMPO CIRURGICO DESCARTAVEL ESTERIL 1.50M X 2.20M ( | B31: 80 | C31: 1 por paciente | D31: 30059020 | E31: UNIDADE | F31: Itens cirúrgicos | G31: KIT BASICO POR CIRURGIA
A32: CAMPO CIRURGICO DESCARTAVEL ESTERIL 1.50M X 1.50M | B32: 80 | C32: 1 por paciente | D32: 30059020 | E32: UNIDADE | F32: Itens cirúrgicos | G32: KIT BASICO POR CIRURGIA
A33: CAMPO PARA MESA DE MAYO ESTERIL 60 CM X 1.40 MT | B33: 70 | C33: 1 por paciente | D33: 30059020 | E33: UNIDADE | F33: Itens cirúrgicos | G33: KIT BASICO POR CIRURGIA
A34: CANETA PARA ELETROCAUTERIO DESCARTAVEL | B34: 70 | C34: 1 por paciente | D34: 90181490 | E34: UNIDADE | F34: Itens cirúrgicos | G34: KIT BASICO POR CIRURGIA
A35: CANULA DE GUEDEL 50MM NR. 0 | B35: 20 | D35: 90183929 | E35: UNIDADE | F35: Itens cirúrgicos | G35: ANESTESIA
A36: CANULA NASOFARINGEA 12FR - 4.0 MM | B36: 8 | D36: 90183929 | E36: UNIDADE | F36: Itens cirúrgicos | G36: ANESTESIA
A37: CANULA NASOFARINGEA 14FR - 4.5 MM | B37: 8 | D37: 90183929 | E37: UNIDADE | F37: Itens cirúrgicos | G37: ANESTESIA
A38: CANULA NASOFARINGEA 16FR - 5.5 MM | B38: 8 | D38: 90183929 | E38: UNIDADE | F38: Itens cirúrgicos | G38: ANESTESIA
A39: CANULA NASOFARINGEA 18FR | B39: 8
A40: CÂNULA NASOFARÍNGEA 28FR
...

Sheet Planilha1
B3: Medicações | C3: Lote | D3: Vencimento | E3: Coluna3 | F3: Quantidade | G3: Necessario | H3: Caixa
B4: XYLESTESIN CLORIDRATO DE LIDOCAÍNA 2,0% 20MG/ML 20ML | C4: 50018091 | D4: 46054 | E4: UN | F4: 16 | H4: DAB 01
B5: XYLESTESIN LIDOCAÍNA 10% 100MG/ML - 50ML | C5: 50020182 | D5: 46691 | E5: UN | F5: 1 | H5: DAB 01
B6: DANTROLEN IV DANTROLENO SÓDICO 20MG | C6: 50022375 | D6: 46752 | E6: - | F6: 3 | H6: OR 06
B7: DANTROLEN IV DANTROLENO SÓDICO 20MG | C7: - | D7: - | E7: UN | F7: 3 | H7: AN 20
B8: SULFATO DE TERBUTALINA 0,5 MG - 1 ML | C8: 2515166 | D8: 46569 | E8: UN | F8: 4 | H8: OR 11
B9: AEROFIN SPRAY - SALBUTAMOL 100 MCG/DOSE 200 DOSES | C9: 2425211 | D9: 46356 | E9: UN | F9: 1 | H9: OR 11
B10: NARIDRIN - CLORIDRATO DE NAFAZOLINA + MALEATO DE MEPIRAMINA + DEXPANTENOL 1MG/ML + 0,2MG/ML + 5MG/ML | C10: 4N5849 | D10: 46784 | E10: UN | F10: 1 | H10: OR 11
B11: ETILEFRIL CLOR. DE ETILEDFRINA 10MG/ML 1ML ADUL/PED | C11: 2448216 | D11: 46357 | E11: UN | F11: 12 | H11: DAB 01
B12: SUCCITRAT - CLORE. DE SUXAMETÔNIO 100MG | C12: 24070177 | D12: 46174 | E12: UN | F12: 10 | H12: DAB 01
B13: FOSFATO SÓDICO DE DEXAMETASONA 4MG/ML IV/IM | C13: DX25B025 | D13: 46388 | E13: UN | F13: =1+19 -> 20 | H13: DAB 01 / AN 15
B14: BRIDION 200 MG/ML - 2ML | C14: A102959 | D14: 46023 | E14: UN | F14: 1 | H14: DAB 01
B15: FENILEFRIN - CLORIDRATO DE FENILEFRINA 10MG/ML - 1ML | C15: 50014479 | D15: 46143 | E15: UN | F15: 20 | H15: DAB 01
B16: PARINEX - HEPARINA SÓDICA SUÍNA - 5ML | C16: U027/25 | D16: 46266 | E16: UN | F16: 20 | H16: DAB 01
B17: TROMETAMOL CETOROLACO 30MG/ML - 1ML I.M./I.V. | C17: BH-007/24 | D17: 46235 | E17: UN | F17: 9 | H17: DAB 01
B18: NORMASTIG METILSULFATO DE NEOSTIGMINA 0,5MG/ML | C18: 2523019H | D18: 46508 | E18: UN | F18: 20 | H18: DAB 01
B19: CEFAZOLINA SÓDICA 1MG VIA INTRAVENOSA | C19: 10577 | D19: 46419 | E19: UN | F19: 12 | H19: DAB 01
B20: SULFATO DE TERBUTALINA 0,5 MG - 1 ML | C20: AV-002/25 | D20: 46447 | E20: UN | F20: 49 | H20: DAB 01
B21: FUROSEMIDA 10MG/ML - 2ML | C21: 25050480 | D21: 46508 | E21: UN | F21: =3+50 -> 53 | H21: DAB 01 / AN 15
B22: CLORID. DE AMIODARONA 50MG/ML - 3ML | C22: AD-027/24 | D22: 46296 | E22: UN | F22: 45 | H22: DAB 01
B23: DIFENIDRIN CLORID. DE DIFENIDRAMINA 50MG/ML - 1 ML | C23: 50025174 | D23: 46784 | E23: UN | F23: 12 | H23: DAB 01
B24: UNIFEDRINE 50MG/ML - SULFATO DE EFEDRINA - 1 ML | C24: 2432348.A | D24: 46235 | E24: UN | F24: 12 | H24: DAB 01
B25: CLORID. DE ONDANSETRONA 2MG/ML - 2ML | C25: 5030150 | D25: 46447 | E25: UN | F25: 12 | H25: DAB 01
B26: CLORID. DE NAXOLONA 0,4MG/ML - 1 ML | C26: BA006/24 | D26: 46204 | E26: UN | F26: 22 | H26: DAB 01
B27: CLONIDIN CLORID. DE CLONIDINA 150 MCG/ML - 1ML | C27: 50023052 | D27: 46357 | E27: UN | F27: 13 | H27: DAB 01
B28: NEOCAÍNA - CLORIDRATO DE BUPIVACAÍNA 0,50% 5MG/ML 20ML - S/ VASO CONSTRITOR | C28: 50024029 | D28: 46753 | E28: UN | F28: 3 | H28: DAB 01
B29: SULFATO DE ATROPINA 0,25 MG/ML IV/IM/SC | C29: AT24L030 | D29: 46296 | E29: UN | F29: 33 | H29: AN 15
B30: ETOMIDATO 2MG/ML - 10 ML | C30: 50024334 | D30: 46419 | E30: UN | F30: 44 | H30: AN 15
B31: PROPOFOL 10MG/ML ADUL/PED. - 20ML | C31: AOHO702A | D31: 46356 | E31: UN | F31: 9 | H31: AN 15
B32: MIDAZOLAM 5MG/ML IV/IM | C32: AP-025/25 | D32: 46419 | E32: UN | F32: 43 | H32: AN 15
B33: ÁCIDO TRANEXÂMICO 50MG/ML - 5ML | C33: BD-015/25 | D33: 46388 | E33: UN | F33: =1+34 -> 35 | H33: AN 15
B34: NUBAIN CLORID. DE NALBUFINA 10MG/ML - 1 ML | C34: 50021506 | D34: 46692 | E34: UN | F34: 10 | H34: AN 15
B35: FLUMAZENIL 0,1 MG/ML - 5 ML | C35: BF-002/25 | D35: 46266 | E35: UN | F35: 15 | H35: AN 15
B36: KETAMIN NP CLORID. DE ESCETAMINA 50MG/ML - 2 ML | C36: 50025872 | D36: 46447 | E36: UN | F36: 9 | H36: AN 15
B37: PAMERGAN CLORID. DE PROMETAZINA 25MG/ML - 2 ML | C37: 50028182 | D37: 46508 | E37: UN | F37: 15 | H37: AN 15
B38: CITRATO DE FENTANILA 50MGC/ML - 2 ML EPI-IV-IM | C38: AS-047/25M | D38: 46447 | E38: UN | F38: 10 | H38: AN 15
B39: ADENOSINA 3MG/ML I.V. - 2 ML | C39: BC-013/24M | D39: 46296 | E39: UN | F39: 17 | H39: AN 15
B40: SUCCINATO SÓDICO DE HIDROCORTISONA 500MG EM PÓ INJETÁVEL | C40: 25060122 | D40: 46508 | E40: UN | F40: 20 | H40: AN 15
B41: ENCRISE - VASOPRESSINA 20 U/ML - AMP. DE 1 ML | C41: 40709684 | D41: 46326 | E41: UN | F41: 10 | H41: AN 15
B42: AMINOFILINA 24MG/ML - AMP. 10 ML | C42: E-008/24M | D42: 46143 | E42: UN | F42: 100 | H42: AN 15
...
